[LOG] Escribiendo logs en: outputs/lstm_improved\log\train_20250831-152232.log
Modelo seleccionado: LSTM
Denormalización (TRAIN only): mean=11.931, std=9.865
Epoch 001 | train_loss=0.09217 | val_MAE=0.30273 | val_RMSE=0.37668
Epoch 002 | train_loss=0.06809 | val_MAE=0.29199 | val_RMSE=0.36306
Epoch 003 | train_loss=0.06616 | val_MAE=0.28480 | val_RMSE=0.35343
Test: loss=0.054860 | MAE=0.2942 | RMSE=0.3642
Traceback (most recent call last):
  File "C:\Users\adrian\Desktop\TFM\TFG-FR\IA_Meteorologica\Réseaux\Data_base_original\LSTM\Univariable\long\neutral\main.py", line 112, in <module>
    main()
  File "C:\Users\adrian\Desktop\TFM\TFG-FR\IA_Meteorologica\Réseaux\Data_base_original\LSTM\Univariable\long\neutral\main.py", line 107, in main
    artifacts = generate_artifacts(cfg, results)
                ^^^^^^^^^^^^^^^^^^^^^^^^^^^^^^^^
  File "C:\Users\adrian\Desktop\TFM\TFG-FR\IA_Meteorologica\Réseaux\Data_base_original\LSTM\Univariable\long\neutral\plots_lstm.py", line 101, in generate_artifacts
    _plot_sample(ax, samples[i].item(), hist_tail, meta.get('H', 336), meta.get('L', 24), i)
                     ^^^^^^^^^^^^^^^
AttributeError: 'dict' object has no attribute 'item'. Did you mean: 'items'?
